Workbook

Sheet Profil Petani
B2: BATUR
B3: No | C3: Nama | D3: Desa | E3: Usia | F3: Pendidikan Terakhir | I3: Rentang Usia | J3: Jumlah (Orang | K3: Presentase
B4: 1 | C4: Arban | D4: Batur | E4: 23 | F4: SMA | I4: 21-30 | J4: 15 | K4: 0.27
B5: 2 | C5: Budi | D5: Batur | E5: 35 | F5: SMA | I5: 31-40 | J5: 17 | K5: 0.31
B6: 3 | C6: Soleh | D6: Batur | E6: 33 | F6: SMA | I6: 41-50 | J6: 17 | K6: 0.31
B7: 4 | C7: Arkan | D7: Batur | E7: 28 | F7: SMA | I7: 51-60 | J7: 6 | K7: 0.11
B8: 5 | C8: Riski | D8: Batur | E8: 32 | F8: SMA
B9: 6 | C9: Reizan | D9: Batur | E9: 24 | F9: SMA | I9: Pendidikan | J9: Jumlah (Orang) | K9: Persentase (%)
B10: 7 | C10: Wiwit | D10: Batur | E10: 26 | F10: SMA | I10: SD | J10: 12 | K10: 0.22
B11: 8 | C11: Alfa | D11: Batur | E11: 28 | F11: SMA | I11: SMP | J11: 6 | K11: 0.11
B12: 9 | C12: Riya | D12: Batur | E12: 26 | F12: SMA | I12: SMA | J12: 26 | K12: 0.47
B13: 10 | C13: Fiera | D13: Batur | E13: 30 | F13: SMA | I13: PT | J13: 11 | K13: 0.2
B14: 11 | C14: Irbab | D14: Batur | E14: 23 | F14: SMA
B15: 12 | C15: Naufal | D15: Batur | E15: 28 | F15: SMA
B17: PASURENAN
B18: No | C18: Nama | D18: Desa | E18: Usia | F18: Pendidikan Terakhir
B19: 1 | C19: Firza | D19: Pasurenan | E19: 23 | F19: SMA
B20: 2 | C20: Muja | D20: Pasurenan | E20: 37 | F20: SMA
B21: 3 | C21: Sura | D21: Pasurenan | E21: 53 | F21: SD
B22: 4 | C22: Manarul | D22: Pasurenan | E22: 26 | F22: PT
B23: 5 | C23: Erga | D23: Pasurenan | E23: 27 | F23: PT
B24: 6 | C24: Afik | D24: Pasurenan | E24: 23 | F24: SMA
B25: 7 | C25: Arifin | D25: Pasurenan | E25: 33 | F25: SMA
B26: 8 | C26: Sukur | D26: Pasurenan | E26: 40 | F26: SD
B28: SUMBEREJO
B29: No | C29: Nama | D29: Desa | E29: Usia | F29: Pendidikan Terakhir
B30: 1 | C30: Hermanto | D30: Sumberejo | E30: 37 | F30: SD
B31: 2 | C31: Rofik | D31: Sumberejo | E31: 45 | F31: PT
B32: 3 | C32: Dawam | D32: Sumberejo | E32: 44 | F32: PT
B33: 4 | C33: Riyadi | D33: Sumberejo | E33: 46 | F33: SD
B34: 5 | C34: Jamaludin | D34: Sumberejo | E34: 46 | F34: SMA
B35: 6 | C35: Priyo | D35: Sumberejo | E35: 42 | F35: PT
B36: 7 | C36: Eko | D36: Sumberejo | E36: 35 | F36: SMA
B37: 8 | C37: Adam | D37: Sumberejo | E37: 38 | F37: PT
B39: KEPASIKSAN
B40: No | C40: Nama | D40: Desa | E40: Usia | F40: Pendidikan Terakhir
B41: 1 | C41: Dasir | D41: Kepakisan | E41: 52 | F41: SMA
B42: 2 | C42: Abas | D42: Kepakisan | E42: 46 | F42: SMA
B43: 3 | C43: Agus | D43: Kepakisan | E43: 42 | F43: SMA
B44: 4 | C44: Fillah | D44: Kepakisan | E44: 22 | F44: PT
...

Sheet 1. Batur
E2: RESPONDEN 1 | AZ2: RESPONDEN 2 | CU2: RESPONDEN 3 | EP2: RESPONDEN 4 | GK2: RESPONDEN 5 | IF2: RESPONDEN 6 | KA2: RESPONDEN 7 | LV2: RESPONDEN 8 | NQ2: RESPONDEN 9 | PL2: RESPONDEN 10 | RG2: RESPONDEN 11 | TB2: RESPONDEN 12 | UY2: BATUR
B4: RELIABILITAS | AW4: RELIABILITAS | CR4: RELIABILITAS | EM4: RELIABILITAS | GH4: RELIABILITAS | IC4: RELIABILITAS | JX4: RELIABILITAS | LS4: RELIABILITAS | NN4: RELIABILITAS | PI4: RELIABILITAS | RD4: RELIABILITAS | SY4: RELIABILITAS
B6: Atribut A | E6: 9 | F6: 8 | G6: 7 | H6: 6 | I6: 5 | J6: 4 | K6: 3 | L6: 2 | M6: 1 | N6: 2 | O6: 3 | P6: 4 | Q6: 5 | R6: 6 | S6: 7 | T6: 8 | U6: 9 | V6: Atribut B | AW6: Atribut A | AZ6: 9 | BA6: 8 | BB6: 7 | BC6: 6 | BD6: 5 | BE6: 4 | BF6: 3 | BG6: 2 | BH6: 1 | BI6: 2 | BJ6: 3 | BK6: 4 | BL6: 5 | BM6: 6 | BN6: 7 | BO6: 8 | BP6: 9 | BQ6: Atribut B | CR6: Atribut A | CU6: 9 | CV6: 8 | CW6: 7 | CX6: 6 | CY6: 5 | CZ6: 4 | DA6: 3 | DB6: 2 | DC6: 1 | DD6: 2 | DE6: 3 | DF6: 4 | DG6: 5 | DH6: 6 | DI6: 7 | DJ6: 8 | DK6: 9 | DL6: Atribut B | EM6: Atribut A | EP6: 9 | EQ6: 8 | ER6: 7 | ES6: 6 | ET6: 5 | EU6: 4 | EV6: 3 | EW6: 2 | EX6: 1 | EY6: 2 | EZ6: 3 | FA6: 4 | FB6: 5 | FC6: 6 | FD6: 7 | FE6: 8 | FF6: 9 | FG6: Atribut B | GH6: Atribut A | GK6: 9 | GL6: 8 | GM6: 7 | GN6: 6 | GO6: 5 | GP6: 4 | GQ6: 3 | GR6: 2 | GS6: 1 | GT6: 2 | GU6: 3 | GV6: 4 | GW6: 5 | GX6: 6 | GY6: 7 | GZ6: 8 | HA6: 9 | HB6: Atribut B | IC6: Atribut A | IF6: 9 | IG6: 8 | IH6: 7 | II6: 6 | IJ6: 5 | IK6: 4 | IL6: 3 | IM6: 2 | IN6: 1 | IO6: 2 | IP6: 3 | IQ6: 4 | IR6: 5 | IS6: 6 | IT6: 7 | IU6: 8 | IV6: 9 | IW6: Atribut B | JX6: Atribut A | KA6: 9 | KB6: 8 | KC6: 7 | KD6: 6 | KE6: 5 | KF6: 4 | KG6: 3 | KH6: 2 | KI6: 1 | KJ6: 2 | KK6: 3 | KL6: 4 | KM6: 5 | KN6: 6 | KO6: 7 | KP6: 8 | KQ6: 9 | KR6: Atribut B | LS6: Atribut A | LV6: 9 | LW6: 8 | LX6: 7 | LY6: 6 | LZ6: 5 | MA6: 4 | MB6: 3 | MC6: 2 | MD6: 1 | ME6: 2 | MF6: 3 | MG6: 4 | MH6: 5 | MI6: 6 | MJ6: 7 | MK6: 8 | ML6: 9 | MM6: Atribut B | NN6: Atribut A | NQ6: 9 | NR6: 8 | NS6: 7 | NT6: 6 | NU6: 5 | NV6: 4 | NW6: 3 | NX6: 2 | NY6: 1 | NZ6: 2 | OA6: 3 | OB6: 4 | OC6: 5 | OD6: 6 | OE6: 7 | OF6: 8 | OG6: 9 | OH6: Atribut B | PI6: Atribut A | PL6: 9 | PM6: 8 | PN6: 7 | PO6: 6 | PP6: 5 | PQ6: 4 | PR6: 3 | PS6: 2 | PT6: 1 | PU6: 2 | PV6: 3 | PW6: 4 | PX6: 5 | PY6: 6 | PZ6: 7 | QA6: 8 | QB6: 9 | QC6: Atribut B | RD6: Atribut A | RG6: 9 | RH6: 8 | RI6: 7 | RJ6: 6 | RK6: 5 | RL6: 4 | RM6: 3 | RN6: 2 | RO6: 1 | RP6: 2 | RQ6: 3 | RR6: 4 | RS6: 5 | RT6: 6 | RU6: 7 | RV6: 8 | RW6: 9 | RX6: Atribut B | SY6: Atribut A | TB6: 9 | TC6: 8 | TD6: 7 | TE6: 6 | TF6: 5 | TG6: 4 | TH6: 3 | TI6: 2 | TJ6: 1 | TK6: 2 | TL6: 3 | TM6: 4 | TN6: 5 | TO6: 6 | TP6: 7 | TQ6: 8 | TR6: 9 | TS6: Atribut B
B7: Pesanan Kondisi Sempurna | V7: Akurasi Pemenuhan | AC7: Pesanan Kondisi Sempurna | AE7: Akurasi Pemenuhan | AG7: Kesesuaian Jumlah Produk | AI7: Kesesuaian Jenis Produk | AK7: Kesesuaian Lokasi pengiriman | AM7: Kesesuaian Waktu Pengiriman | AO7: Akurasi Kondisi Pesanan | AQ7: Kelayakan Produk | AS7: Kualitas Produk | AW7: Pesanan Kondisi Sempurna | BQ7: Akurasi Pemenuhan | BX7: Pesanan Kondisi Sempurna | BZ7: Akurasi Pemenuhan | CB7: Kesesuaian Jumlah Produk | CD7: Kesesuaian Jenis Produk | CF7: Kesesuaian Lokasi pengiriman | CH7: Kesesuaian Waktu Pengiriman | CJ7: Akurasi Kondisi Pesanan | CL7: Kelayakan Produk | CN7: Kualitas Produk | CR7: Pesanan Kondisi Sempurna | DL7: Akurasi Pemenuhan | DS7: Pesanan Kondisi Sempurna | DU7: Akurasi Pemenuhan | DW7: Kesesuaian Jumlah Produk | DY7: Kesesuaian Jenis Produk | EA7: Kesesuaian Lokasi pengiriman | EC7: Kesesuaian Waktu Pengiriman | EE7: Akurasi Kondisi Pesanan | EG7: Kelayakan Produk | EI7: Kualitas Produk | EM7: Pesanan Kondisi Sempurna | FG7: Akurasi Pemenuhan | FN7: Pesanan Kondisi Sempurna | FP7: Akurasi Pemenuhan | FR7: Kesesuaian Jumlah Produk | FT7: Kesesuaian Jenis Produk | FV7: Kesesuaian Lokasi pengiriman | FX7: Kesesuaian Waktu Pengiriman | FZ7: Akurasi Kondisi Pesanan | GB7: Kelayakan Produk | GD7: Kualitas Produk | GH7: Pesanan Kondisi Sempurna | HB7: Akurasi Pemenuhan | HI7: Pesanan Kondisi Sempurna | HK7: Akurasi Pemenuhan | HM7: Kesesuaian Jumlah Produk | HO7: Kesesuaian Jenis Produk | HQ7: Kesesuaian Lokasi pengiriman | HS7: Kesesuaian Waktu Pengiriman | HU7: Akurasi Kondisi Pesanan | HW7: Kelayakan Produk | HY7: Kualitas Produk | IC7: Pesanan Kondisi Sempurna | IW7: Akurasi Pemenuhan | JD7: Pesanan Kondisi Sempurna | JF7: Akurasi Pemenuhan | JH7: Kesesuaian Jumlah Produk | JJ7: Kesesuaian Jenis Produk | JL7: Kesesuaian Lokasi pengiriman | JN7: Kesesuaian Waktu Pengiriman | JP7: Akurasi Kondisi Pesanan | JR7: Kelayakan Produk | JT7: Kualitas Produk | JX7: Pesanan Kondisi Sempurna | KR7: Akurasi Pemenuhan | KY7: Pesanan Kondisi Sempurna | LA7: Akurasi Pemenuhan | LC7: Kesesuaian Jumlah Produk | LE7: Kesesuaian Jenis Produk | LG7: Kesesuaian Lokasi pengiriman | LI7: Kesesuaian Waktu Pengiriman | LK7: Akurasi Kondisi Pesanan | LM7: Kelayakan Produk | LO7: Kualitas Produk | LS7: Pesanan Kondisi Sempurna | MM7: Akurasi Pemenuhan | MT7: Pesanan Kondisi Sempurna | MV7: Akurasi Pemenuhan | MX7: Kesesuaian Jumlah Produk | MZ7: Kesesuaian Jenis Produk | NB7: Kesesuaian Lokasi pengiriman | ND7: Kesesuaian Waktu Pengiriman | NF7: Akurasi Kondisi Pesanan | NH7: Kelayakan Produk | NJ7: Kualitas Produk | NN7: Pesanan Kondisi Sempurna | OH7: Akurasi Pemenuhan | OO7: Pesanan Kondisi Sempurna | OQ7: Akurasi Pemenuhan | OS7: Kesesuaian Jumlah Produk | OU7: Kesesuaian Jenis Produk | OW7: Kesesuaian Lokasi pengiriman | OY7: Kesesuaian Waktu Pengiriman | PA7: Akurasi Kondisi Pesanan | PC7: Kelayakan Produk | PE7: Kualitas Produk | PI7: Pesanan Kondisi Sempurna | QC7: Akurasi Pemenuhan | QJ7: Pesanan Kondisi Sempurna | QL7: Akurasi Pemenuhan | QN7: Kesesuaian Jumlah Produk | QP7: Kesesuaian Jenis Produk | QR7: Kesesuaian Lokasi pengiriman | QT7: Kesesuaian Waktu Pengiriman | QV7: Akurasi Kondisi Pesanan | QX7: Kelayakan Produk | QZ7: Kualitas Produk | RD7: Pesanan Kondisi Sempurna | RX7: Akurasi Pemenuhan | SE7: Pesanan Kondisi Sempurna | SG7: Akurasi Pemenuhan | SI7: Kesesuaian Jumlah Produk | SK7: Kesesuaian Jenis Produk | SM7: Kesesuaian Lokasi pengiriman | SO7: Kesesuaian Waktu Pengiriman | SQ7: Akurasi Kondisi Pesanan | SS7: Kelayakan Produk | SU7: Kualitas Produk | SY7: Pesanan Kondisi Sempurna | TS7: Akurasi Pemenuhan | TZ7: Pesanan Kondisi Sempurna | UB7: Akurasi Pemenuhan | UD7: Kesesuaian Jumlah Produk | UF7: Kesesuaian Jenis Produk | UH7: Kesesuaian Lokasi pengiriman | UJ7: Kesesuaian Waktu Pengiriman | UL7: Akurasi Kondisi Pesanan | UN7: Kelayakan Produk | UP7: Kualitas Produk | UZ7: Pesanan Kondisi Sempurna | VB7: Akurasi Pemenuhan | VD7: Kesesuaian Jumlah Produk | VF7: Kesesuaian Jenis Produk | VH7: Kesesuaian Lokasi pengiriman | VJ7: Kesesuaian Waktu Pengiriman | VL7: Akurasi Kondisi Pesanan | VN7: Kelayakan Produk | VP7: Kualitas Produk
B8: Pesanan Kondisi Sempurna | V8: Kesesuaian Jumlah Produk | AW8: Pesanan Kondisi Sempurna | BQ8: Kesesuaian Jumlah Produk | CR8: Pesanan Kondisi Sempurna | DL8: Kesesuaian Jumlah Produk | EM8: Pesanan Kondisi Sempurna | FG8: Kesesuaian Jumlah Produk | GH8: Pesanan Kondisi Sempurna | HB8: Kesesuaian Jumlah Produk | IC8: Pesanan Kondisi Sempurna | IW8: Kesesuaian Jumlah Produk | JX8: Pesanan Kondisi Sempurna | KR8: Kesesuaian Jumlah Produk | LS8: Pesanan Kondisi Sempurna | MM8: Kesesuaian Jumlah Produk | NN8: Pesanan Kondisi Sempurna | OH8: Kesesuaian Jumlah Produk | PI8: Pesanan Kondisi Sempurna | QC8: Kesesuaian Jumlah Produk | RD8: Pesanan Kondisi Sempurna | RX8: Kesesuaian Jumlah Produk | SY8: Pesanan Kondisi Sempurna | TS8: Kesesuaian Jumlah Produk
B9: Pesanan Kondisi Sempurna | V9: Kesesuaian Jenis Produk | AA9: Pesanan Kondisi Sempurna | AC9: 1 | AE9: {=FindRedCellValue(E7:U7)} -> 0.33333333 | AG9: {=FindRedCellValue(E8:U8)} -> 3 | AI9: {=FindRedCellValue(E9:U9)} -> 3 | AK9: {=FindRedCellValue(E10:U10)} -> 0.2 | AM9: {=FindRedCellValue(E11:U11)} -> 0.33333333 | AO9: {=FindRedCellValue(E12:U12)} -> 5 | AQ9: {=FindRedCellValue(E13:U13)} -> 7 | AS9: {=FindRedCellValue(E14:U14)} -> 0.2 | AW9: Pesanan Kondisi Sempurna | BQ9: Kesesuaian Jenis Produk | BV9: Pesanan Kondisi Sempurna | BX9: 1 | BZ9: {=FindRedCellValue(AZ7:BP7)} -> 0.33333333 | CB9: {=FindRedCellValue(AZ8:BP8)} -> 3 | CD9: {=FindRedCellValue(AZ9:BP9)} -> 5 | CF9: {=FindRedCellValue(AZ10:BP10)} -> 0.33333333 | CH9: {=FindRedCellValue(AZ11:BP11)} -> 0.2 | CJ9: {=FindRedCellValue(AZ12:BP12)} -> 3 | CL9: {=FindRedCellValue(AZ13:BP13)} -> 4 | CN9: {=FindRedCellValue(AZ14:BP14)} -> 4 | CR9: Pesanan Kondisi Sempurna | DL9: Kesesuaian Jenis Produk | DQ9: Pesanan Kondisi Sempurna | DS9: 1 | DU9: {=FindRedCellValue(CU7:DK7)} -> 0.33333333 | DW9: {=FindRedCellValue(CU8:DK8)} -> 3 | DY9: {=FindRedCellValue(CU9:DK9)} -> 3 | EA9: {=FindRedCellValue(CU10:DK10)} -> 0.2 | EC9: {=FindRedCellValue(CU11:DK11)} -> 3 | EE9: {=FindRedCellValue(CU12:DK12)} -> 0.2 | EG9: {=FindRedCellValue(CU13:DK13)} -> 5 | EI9: {=FindRedCellValue(CU14:DK14)} -> 5 | EM9: Pesanan Kondisi Sempurna | FG9: Kesesuaian Jenis Produk | FL9: Pesanan Kondisi Sempurna | FN9: 1 | FP9: {=FindRedCellValue(EP7:FF7)} -> 3 | FR9: {=FindRedCellValue(EP8:FF8)} -> 3 | FT9: {=FindRedCellValue(EP9:FF9)} -> 5 | FV9: {=FindRedCellValue(EP10:FF10)} -> 0.33333333 | FX9: {=FindRedCellValue(EP11:FF11)} -> 3 | FZ9: {=FindRedCellValue(EP12:FF12)} -> 0.14285714 | GB9: {=FindRedCellValue(EP13:FF13)} -> 2 | GD9: {=FindRedCellValue(EP14:FF14)} -> 2 | GH9: Pesanan Kondisi Sempurna | HB9: Kesesuaian Jenis Produk | HG9: Pesanan Kondisi Sempurna | HI9: 1 | HK9: {=FindRedCellValue(GK7:HA7)} -> 0.2 | HM9: {=FindRedCellValue(GK8:HA8)} -> 0.33333333 | HO9: {=FindRedCellValue(GK9:HA9)} -> 3 | HQ9: {=FindRedCellValue(GK10:HA10)} -> 0.33333333 | HS9: {=FindRedCellValue(GK11:HA11)} -> 5 | HU9: {=FindRedCellValue(GK12:HA12)} -> 0.5 | HW9: {=FindRedCellValue(GK13:HA13)} -> 3 | HY9: {=FindRedCellValue(GK14:HA14)} -> 5 | IC9: Pesanan Kondisi Sempurna | IW9: Kesesuaian Jenis Produk | JB9: Pesanan Kondisi Sempurna | JD9: 1 | JF9: {=FindRedCellValue(IF7:IV7)} -> 0.2 | JH9: {=FindRedCellValue(IF8:IV8)} -> 0.33333333 | JJ9: {=FindRedCellValue(IF9:IV9)} -> 0.33333333 | JL9: {=FindRedCellValue(IF10:IV10)} -> 0.33333333 | JN9: {=FindRedCellValue(IF11:IV11)} -> 3 | JP9: {=FindRedCellValue(IF12:IV12)} -> 3 | JR9: {=FindRedCellValue(IF13:IV13)} -> 7 | JT9: {=FindRedCellValue(IF14:IV14)} -> 7 | JX9: Pesanan Kondisi Sempurna | KR9: Kesesuaian Jenis Produk | KW9: Pesanan Kondisi Sempurna | KY9: 1 | LA9: {=FindRedCellValue(KA7:KQ7)} -> 0.33333333 | LC9: {=FindRedCellValue(KA8:KQ8)} -> 3 | LE9: {=FindRedCellValue(KA9:KQ9)} -> 3 | LG9: {=FindRedCellValue(KA10:KQ10)} -> 0.2 | LI9: {=FindRedCellValue(KA11:KQ11)} -> 3 | LK9: {=FindRedCellValue(KA12:KQ12)} -> 0.2 | LM9: {=FindRedCellValue(KA13:KQ13)} -> 5 | LO9: {=FindRedCellValue(KA14:KQ14)} -> 5 | LS9: Pesanan Kondisi Sempurna | MM9: Kesesuaian Jenis Produk | MR9: Pesanan Kondisi Sempurna | MT9: 1 | MV9: {=FindRedCellValue(LV7:ML7)} -> 3 | MX9: {=FindRedCellValue(LV8:ML8)} -> 3 | MZ9: {=FindRedCellValue(LV9:ML9)} -> 5 | NB9: {=FindRedCellValue(LV10:ML10)} -> 0.33333333 | ND9: {=FindRedCellValue(LV11:ML11)} -> 3 | NF9: {=FindRedCellValue(LV12:ML12)} -> 0.14285714 | NH9: {=FindRedCellValue(LV13:ML13)} -> 2 | NJ9: {=FindRedCellValue(LV14:ML14)} -> 2 | NN9: Pesanan Kondisi Sempurna | OH9: Kesesuaian Jenis Produk | OM9: Pesanan Kondisi Sempurna | OO9: 1 | OQ9: {=FindRedCellValue(NQ7:OG7)} -> 0.33333333 | OS9: {=FindRedCellValue(NQ8:OG8)} -> 3 | OU9: {=FindRedCellValue(NQ9:OG9)} -> 3 | OW9: {=FindRedCellValue(NQ10:OG10)} -> 0.2 | OY9: {=FindRedCellValue(NQ11:OG11)} -> 0.33333333 | PA9: {=FindRedCellValue(NQ12:OG12)} -> 5 | PC9: {=FindRedCellValue(NQ13:OG13)} -> 7 | PE9: {=FindRedCellValue(NQ14:OG14)} -> 0.2 | PI9: Pesanan Kondisi Sempurna | QC9: Kesesuaian Jenis Produk | QH9: Pesanan Kondisi Sempurna | QJ9: 1 | QL9: {=FindRedCellValue(PL7:QB7)} -> 0.2 | QN9: {=FindRedCellValue(PL8:QB8)} -> 0.33333333 | QP9: {=FindRedCellValue(PL9:QB9)} -> 0.33333333 | QR9: {=FindRedCellValue(PL10:QB10)} -> 0.33333333 | QT9: {=FindRedCellValue(PL11:QB11)} -> 3 | QV9: {=FindRedCellValue(PL12:QB12)} -> 3 | QX9: {=FindRedCellValue(PL13:QB13)} -> 7 | QZ9: {=FindRedCellValue(PL14:QB14)} -> 7 | RD9: Pesanan Kondisi Sempurna | RX9: Kesesuaian Jenis Produk | SC9: Pesanan Kondisi Sempurna | SE9: 1 | SG9: {=FindRedCellValue(RG7:RW7)} -> 0.33333333 | SI9: {=FindRedCellValue(RG8:RW8)} -> 3 | SK9: {=FindRedCellValue(RG9:RW9)} -> 3 | SM9: {=FindRedCellValue(RG10:RW10)} -> 0.2 | SO9: {=FindRedCellValue(RG11:RW11)} -> 0.33333333 | SQ9: {=FindRedCellValue(RG12:RW12)} -> 5 | SS9: {=FindRedCellValue(RG13:RW13)} -> 7 | SU9: {=FindRedCellValue(RG14:RW14)} -> 0.2 | SY9: Pesanan Kondisi Sempurna | TS9: Kesesuaian Jenis Produk | TX9: Pesanan Kondisi Sempurna | TZ9: 1 | UB9: {=FindRedCellValue(TB7:TR7)} -> 0.33333333 | UD9: {=FindRedCellValue(TB8:TR8)} -> 3 | UF9: {=FindRedCellValue(TB9:TR9)} -> 5 | UH9: {=FindRedCellValue(TB10:TR10)} -> 0.33333333 | UJ9: {=FindRedCellValue(TB11:TR11)} -> 0.2 | UL9: {=FindRedCellValue(TB12:TR12)} -> 3 | UN9: {=FindRedCellValue(TB13:TR13)} -> 4 | UP9: {=FindRedCellValue(TB14:TR14)} -> 4 | UX9: Pesanan Kondisi Sempurna | UZ9: =AVERAGE(AC9,BX9,DS9,FN9,HI9,JD9,KY9,MT9,OO9,QJ9,SE9,TZ9) -> 1 | VB9: =AVERAGE(AE9,BZ9,DU9,FP9,HK9,JF9,LA9,MV9,OQ9,QL9,SG9,UB9) -> 0.74444444 | VD9: =AVERAGE(AG9,CB9,DW9,FR9,HM9,JH9,LC9,MX9,OS9,QN9,SI9,UD9) -> 2.3333333 | VF9: =AVERAGE(AI9,CD9,DY9,FT9,HO9,JJ9,LE9,MZ9,OU9,QP9,SK9,UF9) -> 3.2222222 | VH9: =AVERAGE(AK9,CF9,EA9,FV9,HQ9,JL9,LG9,NB9,OW9,QR9,SM9,UH9) -> 0.27777778 | VJ9: =AVERAGE(AM9,CH9,EC9,FX9,HS9,JN9,LI9,ND9,OY9,QT9,SO9,UJ9) -> 2.0333333 | VL9: =AVERAGE(AO9,CJ9,EE9,FZ9,HU9,JP9,LK9,NF9,PA9,QV9,SQ9,UL9) -> 2.3488095 | VN9: =AVERAGE(AQ9,CL9,EG9,GB9,HW9,JR9,LM9,NH9,PC9,QX9,SS9,UN9) -> 5 | VP9: =AVERAGE(AS9,CN9,EI9,GD9,HY9,JT9,LO9,NJ9,PE9,QZ9,SU9,UP9) -> 3.4666667
B10: Pesanan Kondisi Sempurna | V10: Kesesuaian Lokasi Pengiriman | AW10: Pesanan Kondisi Sempurna | BQ10: Kesesuaian Lokasi Pengiriman | CR10: Pesanan Kondisi Sempurna | DL10: Kesesuaian Lokasi Pengiriman | EM10: Pesanan Kondisi Sempurna | FG10: Kesesuaian Lokasi Pengiriman | GH10: Pesanan Kondisi Sempurna | HB10: Kesesuaian Lokasi Pengiriman | IC10: Pesanan Kondisi Sempurna | IW10: Kesesuaian Lokasi Pengiriman | JX10: Pesanan Kondisi Sempurna | KR10: Kesesuaian Lokasi Pengiriman | LS10: Pesanan Kondisi Sempurna | MM10: Kesesuaian Lokasi Pengiriman | NN10: Pesanan Kondisi Sempurna | OH10: Kesesuaian Lokasi Pengiriman | PI10: Pesanan Kondisi Sempurna | QC10: Kesesuaian Lokasi Pengiriman | RD10: Pesanan Kondisi Sempurna | RX10: Kesesuaian Lokasi Pengiriman | SY10: Pesanan Kondisi Sempurna | TS10: Kesesuaian Lokasi Pengiriman
B11: Pesanan Kondisi Sempurna | V11: Kesesuaian Waktu Pengiriman | AA11: Akurasi Pemenuhan | AC11: =1/AE9 -> 3 | AE11: 1 | AG11: {=FindRedCellValue(E17:U17)} -> 3 | AI11: {=FindRedCellValue(E18:U18)} -> 5 | AK11: {=FindRedCellValue(E19:U19)} -> 0.2 | AM11: {=FindRedCellValue(E20:U20)} -> 0.14285714 | AO11: {=FindRedCellValue(E21:U21)} -> 3 | AQ11: {=FindRedCellValue(E22:U22)} -> 3 | AS11: {=FindRedCellValue(E23:U23)} -> 0.33333333 | AW11: Pesanan Kondisi Sempurna | BQ11: Kesesuaian Waktu Pengiriman | BV11: Akurasi Pemenuhan | BX11: =1/BZ9 -> 3 | BZ11: 1 | CB11: {=FindRedCellValue(AZ17:BP17)} -> 3 | CD11: {=FindRedCellValue(AZ18:BP18)} -> 3 | CF11: {=FindRedCellValue(AZ19:BP19)} -> 0.33333333 | CH11: {=FindRedCellValue(AZ20:BP20)} -> 0.33333333 | CJ11: {=FindRedCellValue(AZ21:BP21)} -> 0.33333333 | CL11: {=FindRedCellValue(AZ22:BP22)} -> 5 | CN11: {=FindRedCellValue(AZ23:BP23)} -> 3 | CR11: Pesanan Kondisi Sempurna | DL11: Kesesuaian Waktu Pengiriman | DQ11: Akurasi Pemenuhan | DS11: =1/DU9 -> 3 | DU11: 1 | DW11: {=FindRedCellValue(CU17:DK17)} -> 3 | DY11: {=FindRedCellValue(CU18:DK18)} -> 5 | EA11: {=FindRedCellValue(CU19:DK19)} -> 0.33333333 | EC11: {=FindRedCellValue(CU20:DK20)} -> 0.33333333 | EE11: {=FindRedCellValue(CU21:DK21)} -> 3 | EG11: {=FindRedCellValue(CU22:DK22)} -> 3 | EI11: {=FindRedCellValue(CU23:DK23)} -> 3 | EM11: Pesanan Kondisi Sempurna | FG11: Kesesuaian Waktu Pengiriman | FL11: Akurasi Pemenuhan | FN11: =1/FP9 -> 0.33333333 | FP11: 1 | FR11: {=FindRedCellValue(EP17:FF17)} -> 0.33333333 | FT11: {=FindRedCellValue(EP18:FF18)} -> 5 | FV11: {=FindRedCellValue(EP19:FF19)} -> 0.33333333 | FX11: {=FindRedCellValue(EP20:FF20)} -> 3 | FZ11: {=FindRedCellValue(EP21:FF21)} -> 0.2 | GB11: {=FindRedCellValue(EP22:FF22)} -> 3 | GD11: {=FindRedCellValue(EP23:FF23)} -> 0.2 | GH11: Pesanan Kondisi Sempurna | HB11: Kesesuaian Waktu Pengiriman | HG11: Akurasi Pemenuhan | HI11: =1/HK9 -> 5 | HK11: 1 | HM11: {=FindRedCellValue(GK17:HA17)} -> 3 | HO11: {=FindRedCellValue(GK18:HA18)} -> 5 | HQ11: {=FindRedCellValue(GK19:HA19)} -> 0.14285714 | HS11: {=FindRedCellValue(GK20:HA20)} -> 0.11111111 | HU11: {=FindRedCellValue(GK21:HA21)} -> 3 | HW11: {=FindRedCellValue(GK22:HA22)} -> 7 | HY11: {=FindRedCellValue(GK23:HA23)} -> 7 | IC11: Pesanan Kondisi Sempurna | IW11: Kesesuaian Waktu Pengiriman | JB11: Akurasi Pemenuhan | JD11: =1/JF9 -> 5 | JF11: 1 | JH11: {=FindRedCellValue(IF17:IV17)} -> 0.33333333 | JJ11: {=FindRedCellValue(IF18:IV18)} -> 0.33333333 | JL11: {=FindRedCellValue(IF19:IV19)} -> 0.33333333 | JN11: {=FindRedCellValue(IF20:IV20)} -> 3 | JP11: {=FindRedCellValue(IF21:IV21)} -> 3 | JR11: {=FindRedCellValue(IF22:IV22)} -> 3 | JT11: {=FindRedCellValue(IF23:IV23)} -> 3 | JX11: Pesanan Kondisi Sempurna | KR11: Kesesuaian Waktu Pengiriman | KW11: Akurasi Pemenuhan | KY11: =1/LA9 -> 3 | LA11: 1 | LC11: {=FindRedCellValue(KA17:KQ17)} -> 3 | LE11: {=FindRedCellValue(KA18:KQ18)} -> 5 | LG11: {=FindRedCellValue(KA19:KQ19)} -> 0.33333333 | LI11: {=FindRedCellValue(KA20:KQ20)} -> 0.33333333 | LK11: {=FindRedCellValue(KA21:KQ21)} -> 3 | LM11: {=FindRedCellValue(KA22:KQ22)} -> 3 | LO11: {=FindRedCellValue(KA23:KQ23)} -> 3 | LS11: Pesanan Kondisi Sempurna | MM11: Kesesuaian Waktu Pengiriman | MR11: Akurasi Pemenuhan | MT11: =1/MV9 -> 0.33333333 | MV11: 1 | MX11: {=FindRedCellValue(LV17:ML17)} -> 0.33333333 | MZ11: {=FindRedCellValue(LV18:ML18)} -> 5 | NB11: {=FindRedCellValue(LV19:ML19)} -> 0.33333333 | ND11: {=FindRedCellValue(LV20:ML20)} -> 3 | NF11: {=FindRedCellValue(LV21:ML21)} -> 0.2 | NH11: {=FindRedCellValue(LV22:ML22)} -> 3 | NJ11: {=FindRedCellValue(LV23:ML23)} -> 0.2 | NN11: Pesanan Kondisi Sempurna | OH11: Kesesuaian Waktu Pengiriman | OM11: Akurasi Pemenuhan | OO11: =1/OQ9 -> 3 | OQ11: 1 | OS11: {=FindRedCellValue(NQ17:OG17)} -> 3 | OU11: {=FindRedCellValue(NQ18:OG18)} -> 5 | OW11: {=FindRedCellValue(NQ19:OG19)} -> 0.2 | OY11: {=FindRedCellValue(NQ20:OG20)} -> 0.14285714 | PA11: {=FindRedCellValue(NQ21:OG21)} -> 3 | PC11: {=FindRedCellValue(NQ22:OG22)} -> 3 | PE11: {=FindRedCellValue(NQ23:OG23)} -> 0.33333333 | PI11: Pesanan Kondisi Sempurna | QC11: Kesesuaian Waktu Pengiriman | QH11: Akurasi Pemenuhan | QJ11: =1/QL9 -> 5 | QL11: 1 | QN11: {=FindRedCellValue(PL17:QB17)} -> 0.33333333 | QP11: {=FindRedCellValue(PL18:QB18)} -> 0.33333333 | QR11: {=FindRedCellValue(PL19:QB19)} -> 0.33333333 | QT11: {=FindRedCellValue(PL20:QB20)} -> 3 | QV11: {=FindRedCellValue(PL21:QB21)} -> 3 | QX11: {=FindRedCellValue(PL22:QB22)} -> 3 | QZ11: {=FindRedCellValue(PL23:QB23)} -> 3 | RD11: Pesanan Kondisi Sempurna | RX11: Kesesuaian Waktu Pengiriman | SC11: Akurasi Pemenuhan | SE11: =1/SG9 -> 3 | SG11: 1 | SI11: {=FindRedCellValue(RG17:RW17)} -> 3 | SK11: {=FindRedCellValue(RG18:RW18)} -> 5 | SM11: {=FindRedCellValue(RG19:RW19)} -> 0.2 | SO11: {=FindRedCellValue(RG20:RW20)} -> 0.14285714 | SQ11: {=FindRedCellValue(RG21:RW21)} -> 3 | SS11: {=FindRedCellValue(RG22:RW22)} -> 3 | SU11: {=FindRedCellValue(RG23:RW23)} -> 0.33333333 | SY11: Pesanan Kondisi Sempurna | TS11: Kesesuaian Waktu Pengiriman | TX11: Akurasi Pemenuhan | TZ11: =1/UB9 -> 3 | UB11: 1 | UD11: {=FindRedCellValue(TB17:TR17)} -> 3 | UF11: {=FindRedCellValue(TB18:TR18)} -> 3 | UH11: {=FindRedCellValue(TB19:TR19)} -> 0.33333333 | UJ11: {=FindRedCellValue(TB20:TR20)} -> 0.33333333 | UL11: {=FindRedCellValue(TB21:TR21)} -> 0.33333333 | UN11: {=FindRedCellValue(TB22:TR22)} -> 5 | UP11: {=FindRedCellValue(TB23:TR23)} -> 3 | UX11: Akurasi Pemenuhan | UZ11: =AVERAGE(AC11,BX11,DS11,FN11,HI11,JD11,KY11,MT11,OO11,QJ11,SE11,TZ11) -> 3.0555556 | VB11: =AVERAGE(AE11,BZ11,DU11,FP11,HK11,JF11,LA11,MV11,OQ11,QL11,SG11,UB11) -> 1 | VD11: =AVERAGE(AG11,CB11,DW11,FR11,HM11,JH11,LC11,MX11,OS11,QN11,SI11,UD11) -> 2.1111111 | VF11: =AVERAGE(AI11,CD11,DY11,FT11,HO11,JJ11,LE11,MZ11,OU11,QP11,SK11,UF11) -> 3.8888889 | VH11: =AVERAGE(AK11,CF11,EA11,FV11,HQ11,JL11,LG11,NB11,OW11,QR11,SM11,UH11) -> 0.28412698 | VJ11: =AVERAGE(AM11,CH11,EC11,FX11,HS11,JN11,LI11,ND11,OY11,QT11,SO11,UJ11) -> 1.1560847 | VL11: =AVERAGE(AO11,CJ11,EE11,FZ11,HU11,JP11,LK11,NF11,PA11,QV11,SQ11,UL11) -> 2.0888889 | VN11: =AVERAGE(AQ11,CL11,EG11,GB11,HW11,JR11,LM11,NH11,PC11,QX11,SS11,UN11) -> 3.6666667 | VP11: =AVERAGE(AS11,CN11,EI11,GD11,HY11,JT11,LO11,NJ11,PE11,QZ11,SU11,UP11) -> 2.2
B12: Pesanan Kondisi Sempurna | V12: Akurasi Kondisi Pesanan | AW12: Pesanan Kondisi Sempurna | BQ12: Akurasi Kondisi Pesanan | CR12: Pesanan Kondisi Sempurna | DL12: Akurasi Kondisi Pesanan | EM12: Pesanan Kondisi Sempurna | FG12: Akurasi Kondisi Pesanan | GH12: Pesanan Kondisi Sempurna | HB12: Akurasi Kondisi Pesanan | IC12: Pesanan Kondisi Sempurna | IW12: Akurasi Kondisi Pesanan | JX12: Pesanan Kondisi Sempurna | KR12: Akurasi Kondisi Pesanan | LS12: Pesanan Kondisi Sempurna | MM12: Akurasi Kondisi Pesanan | NN12: Pesanan Kondisi Sempurna | OH12: Akurasi Kondisi Pesanan | PI12: Pesanan Kondisi Sempurna | QC12: Akurasi Kondisi Pesanan | RD12: Pesanan Kondisi Sempurna | RX12: Akurasi Kondisi Pesanan | SY12: Pesanan Kondisi Sempurna | TS12: Akurasi Kondisi Pesanan
B13: Pesanan Kondisi Sempurna | V13: Kelayakan Produk | AA13: Kesesuaian Jumlah Produk | AC13: =1/AG9 -> 0.33333333 | AE13: =1/AG11 -> 0.33333333 | AG13: 1 | AI13: {=FindRedCellValue(E26:U26)} -> 5 | AK13: {=FindRedCellValue(E27:U27)} -> 0.33333333 | AM13: {=FindRedCellValue(E28:U28)} -> 7 | AO13: {=FindRedCellValue(E29:U29)} -> 9 | AQ13: {=FindRedCellValue(E30:U30)} -> 0.14285714 | AS13: {=FindRedCellValue(E31:U31)} -> 0.14285714 | AW13: Pesanan Kondisi Sempurna | BQ13: Kelayakan Produk | BV13: Kesesuaian Jumlah Produk | BX13: =1/CB9 -> 0.33333333 | BZ13: =1/CB11 -> 0.33333333 | CB13: 1 | CD13: {=FindRedCellValue(AZ26:BP26)} -> 3 | CF13: {=FindRedCellValue(AZ27:BP27)} -> 0.33333333 | CH13: {=FindRedCellValue(AZ28:BP28)} -> 3 | CJ13: {=FindRedCellValue(AZ29:BP29)} -> 5 | CL13: {=FindRedCellValue(AZ30:BP30)} -> 3 | CN13: {=FindRedCellValue(AZ31:BP31)} -> 5 | CR13: Pesanan Kondisi Sempurna | DL13: Kelayakan Produk | DQ13: Kesesuaian Jumlah Produk | DS13: =1/DW9 -> 0.33333333 | DU13: =1/DW11 -> 0.33333333 | DW13: 1 | DY13: {=FindRedCellValue(CU26:DK26)} -> 3 | EA13: {=FindRedCellValue(CU27:DK27)} -> 0.14285714 | EC13: {=FindRedCellValue(CU28:DK28)} -> 5 | EE13: {=FindRedCellValue(CU29:DK29)} -> 5 | EG13: {=FindRedCellValue(CU30:DK30)} -> 3 | EI13: {=FindRedCellValue(CU31:DK31)} -> 0.2 | EM13: Pesanan Kondisi Sempurna | FG13: Kelayakan Produk | FL13: Kesesuaian Jumlah Produk | FN13: =1/FR9 -> 0.33333333 | FP13: =1/FR11 -> 3 | FR13: 1 | FT13: {=FindRedCellValue(EP26:FF26)} -> 0.33333333 | FV13: {=FindRedCellValue(EP27:FF27)} -> 0.33333333 | FX13: {=FindRedCellValue(EP28:FF28)} -> 5 | FZ13: {=FindRedCellValue(EP29:FF29)} -> 3 | GB13: {=FindRedCellValue(EP30:FF30)} -> 3 | GD13: {=FindRedCellValue(EP31:FF31)} -> 3 | GH13: Pesanan Kondisi Sempurna | HB13: Kelayakan Produk | HG13: Kesesuaian Jumlah Produk | HI13: =1/HM9 -> 3 | HK13: =1/HM11 -> 0.33333333 | HM13: 1 | HO13: {=FindRedCellValue(GK26:HA26)} -> 3 | HQ13: {=FindRedCellValue(GK27:HA27)} -> 0.33333333 | HS13: {=FindRedCellValue(GK28:HA28)} -> 3 | HU13: {=FindRedCellValue(GK29:HA29)} -> 3 | HW13: {=FindRedCellValue(GK30:HA30)} -> 0.33333333 | HY13: {=FindRedCellValue(GK31:HA31)} -> 3 | IC13: Pesanan Kondisi Sempurna | IW13: Kelayakan Produk | JB13: Kesesuaian Jumlah Produk | JD13: =1/JH9 -> 3 | JF13: =1/JH11 -> 3 | JH13: 1 | JJ13: {=FindRedCellValue(IF26:IV26)} -> 0.33333333 | JL13: {=FindRedCellValue(IF27:IV27)} -> 0.33333333 | JN13: {=FindRedCellValue(IF28:IV28)} -> 3 | JP13: {=FindRedCellValue(IF29:IV29)} -> 3 | JR13: {=FindRedCellValue(IF30:IV30)} -> 3 | JT13: {=FindRedCellValue(IF31:IV31)} -> 3 | JX13: Pesanan Kondisi Sempurna | KR13: Kelayakan Produk | KW13: Kesesuaian Jumlah Produk | KY13: =1/LC9 -> 0.33333333 | LA13: =1/LC11 -> 0.33333333 | LC13: 1 | LE13: {=FindRedCellValue(KA26:KQ26)} -> 3 | LG13: {=FindRedCellValue(KA27:KQ27)} -> 0.14285714 | LI13: {=FindRedCellValue(KA28:KQ28)} -> 5 | LK13: {=FindRedCellValue(KA29:KQ29)} -> 5 | LM13: {=FindRedCellValue(KA30:KQ30)} -> 3 | LO13: {=FindRedCellValue(KA31:KQ31)} -> 0.2 | LS13: Pesanan Kondisi Sempurna | MM13: Kelayakan Produk | MR13: Kesesuaian Jumlah Produk | MT13: =1/MX9 -> 0.33333333 | MV13: =1/MX11 -> 3 | MX13: 1 | MZ13: {=FindRedCellValue(LV26:ML26)} -> 0.33333333 | NB13: {=FindRedCellValue(LV27:ML27)} -> 0.33333333 | ND13: {=FindRedCellValue(LV28:ML28)} -> 5 | NF13: {=FindRedCellValue(LV29:ML29)} -> 3 | NH13: {=FindRedCellValue(LV30:ML30)} -> 3 | NJ13: {=FindRedCellValue(LV31:ML31)} -> 3 | NN13: Pesanan Kondisi Sempurna | OH13: Kelayakan Produk | OM13: Kesesuaian Jumlah Produk | OO13: =1/OS9 -> 0.33333333 | OQ13: =1/OS11 -> 0.33333333 | OS13: 1 | OU13: {=FindRedCellValue(NQ26:OG26)} -> 5 | OW13: {=FindRedCellValue(NQ27:OG27)} -> 0.33333333 | OY13: {=FindRedCellValue(NQ28:OG28)} -> 7 | PA13: {=FindRedCellValue(NQ29:OG29)} -> 9 | PC13: {=FindRedCellValue(NQ30:OG30)} -> 0.14285714 | PE13: {=FindRedCellValue(NQ31:OG31)} -> 0.14285714 | PI13: Pesanan Kondisi Sempurna | QC13: Kelayakan Produk | QH13: Kesesuaian Jumlah Produk | QJ13: =1/QN9 -> 3 | QL13: =1/QN11 -> 3 | QN13: 1 | QP13: {=FindRedCellValue(PL26:QB26)} -> 0.33333333 | QR13: {=FindRedCellValue(PL27:QB27)} -> 0.33333333 | QT13: {=FindRedCellValue(PL28:QB28)} -> 3 | QV13: {=FindRedCellValue(PL29:QB29)} -> 3 | QX13: {=FindRedCellValue(PL30:QB30)} -> 3 | QZ13: {=FindRedCellValue(PL31:QB31)} -> 3 | RD13: Pesanan Kondisi Sempurna | RX13: Kelayakan Produk | SC13: Kesesuaian Jumlah Produk | SE13: =1/SI9 -> 0.33333333 | SG13: =1/SI11 -> 0.33333333 | SI13: 1 | SK13: {=FindRedCellValue(RG26:RW26)} -> 5 | SM13: {=FindRedCellValue(RG27:RW27)} -> 0.33333333 | SO13: {=FindRedCellValue(RG28:RW28)} -> 7 | SQ13: {=FindRedCellValue(RG29:RW29)} -> 9 | SS13: {=FindRedCellValue(RG30:RW30)} -> 0.14285714 | SU13: {=FindRedCellValue(RG31:RW31)} -> 0.14285714 | SY13: Pesanan Kondisi Sempurna | TS13: Kelayakan Produk | TX13: Kesesuaian Jumlah Produk | TZ13: =1/UD9 -> 0.33333333 | UB13: =1/UD11 -> 0.33333333 | UD13: 1 | UF13: {=FindRedCellValue(TB26:TR26)} -> 3 | UH13: {=FindRedCellValue(TB27:TR27)} -> 0.33333333 | UJ13: {=FindRedCellValue(TB28:TR28)} -> 3 | UL13: {=FindRedCellValue(TB29:TR29)} -> 5 | UN13: {=FindRedCellValue(TB30:TR30)} -> 3 | UP13: {=FindRedCellValue(TB31:TR31)} -> 5 | UX13: Kesesuaian Jumlah Produk | UZ13: =AVERAGE(AC13,BX13,DS13,FN13,HI13,JD13,KY13,MT13,OO13,QJ13,SE13,TZ13) -> 1 | VB13: =AVERAGE(AE13,BZ13,DU13,FP13,HK13,JF13,LA13,MV13,OQ13,QL13,SG13,UB13) -> 1.2222222 | VD13: =AVERAGE(AG13,CB13,DW13,FR13,HM13,JH13,LC13,MX13,OS13,QN13,SI13,UD13) -> 1 | VF13: =AVERAGE(AI13,CD13,DY13,FT13,HO13,JJ13,LE13,MZ13,OU13,QP13,SK13,UF13) -> 2.6111111 | VH13: =AVERAGE(AK13,CF13,EA13,FV13,HQ13,JL13,LG13,NB13,OW13,QR13,SM13,UH13) -> 0.3015873 | VJ13: =AVERAGE(AM13,CH13,EC13,FX13,HS13,JN13,LI13,ND13,OY13,QT13,SO13,UJ13) -> 4.6666667 | VL13: =AVERAGE(AO13,CJ13,EE13,FZ13,HU13,JP13,LK13,NF13,PA13,QV13,SQ13,UL13) -> 5.1666667 | VN13: =AVERAGE(AQ13,CL13,EG13,GB13,HW13,JR13,LM13,NH13,PC13,QX13,SS13,UN13) -> 2.0634921 | VP13: =AVERAGE(AS13,CN13,EI13,GD13,HY13,JT13,LO13,NJ13,PE13,QZ13,SU13,UP13) -> 2.152381
B14: Pesanan Kondisi Sempurna | V14: Kualitas Produk | AW14: Pesanan Kondisi Sempurna | BQ14: Kualitas Produk | CR14: Pesanan Kondisi Sempurna | DL14: Kualitas Produk | EM14: Pesanan Kondisi Sempurna | FG14: Kualitas Produk | GH14: Pesanan Kondisi Sempurna | HB14: Kualitas Produk | IC14: Pesanan Kondisi Sempurna | IW14: Kualitas Produk | JX14: Pesanan Kondisi Sempurna | KR14: Kualitas Produk | LS14: Pesanan Kondisi Sempurna | MM14: Kualitas Produk | NN14: Pesanan Kondisi Sempurna | OH14: Kualitas Produk | PI14: Pesanan Kondisi Sempurna | QC14: Kualitas Produk | RD14: Pesanan Kondisi Sempurna | RX14: Kualitas Produk | SY14: Pesanan Kondisi Sempurna | TS14: Kualitas Produk
AA15: Kesesuaian Jenis Produk | AC15: =1/AI9 -> 0.33333333 | AE15: =1/AI11 -> 0.2 | AG15: =1/AI13 -> 0.2 | AI15: 1 | AK15: {=FindRedCellValue(E34:U34)} -> 0.2 | AM15: {=FindRedCellValue(E35:U35)} -> 3 | AO15: {=FindRedCellValue(E36:U36)} -> 5 | AQ15: {=FindRedCellValue(E37:U37)} -> 0.33333333 | AS15: {=FindRedCellValue(E38:U38)} -> 7 | BV15: Kesesuaian Jenis Produk | BX15: =1/CD9 -> 0.2 | BZ15: =1/CD11 -> 0.33333333 | CB15: =1/CD13 -> 0.33333333 | CD15: 1 | CF15: {=FindRedCellValue(AZ34:BP34)} -> 0.2 | CH15: {=FindRedCellValue(AZ35:BP35)} -> 7 | CJ15: {=FindRedCellValue(AZ36:BP36)} -> 0.33333333 | CL15: {=FindRedCellValue(AZ37:BP37)} -> 5 | CN15: {=FindRedCellValue(AZ38:BP38)} -> 5 | DQ15: Kesesuaian Jenis Produk | DS15: =1/DY9 -> 0.33333333 | DU15: =1/DY11 -> 0.2 | DW15: =1/DY13 -> 0.33333333 | DY15: 1 | EA15: {=FindRedCellValue(CU34:DK34)} -> 0.33333333 | EC15: {=FindRedCellValue(CU35:DK35)} -> 3 | EE15: {=FindRedCellValue(CU36:DK36)} -> 3 | EG15: {=FindRedCellValue(CU37:DK37)} -> 2 | EI15: {=FindRedCellValue(CU38:DK38)} -> 4 | FL15: Kesesuaian Jenis Produk | FN15: =1/FT9 -> 0.2 | FP15: =1/FT11 -> 0.2 | FR15: =1/FT13 -> 3 | FT15: 1 | FV15: {=FindRedCellValue(EP34:FF34)} -> 0.33333333 | FX15: {=FindRedCellValue(EP35:FF35)} -> 0.33333333 | FZ15: {=FindRedCellValue(EP36:FF36)} -> 3 | GB15: {=FindRedCellValue(EP37:FF37)} -> 3 | GD15: {=FindRedCellValue(EP38:FF38)} -> 3 | HG15: Kesesuaian Jenis Produk | HI15: =1/HO9 -> 0.33333333 | HK15: =1/HO11 -> 0.2 | HM15: =1/HO13 -> 0.33333333 | HO15: 1 | HQ15: {=FindRedCellValue(GK34:HA34)} -> 0.2 | HS15: {=FindRedCellValue(GK35:HA35)} -> 3 | HU15: {=FindRedCellValue(GK36:HA36)} -> 5 | HW15: {=FindRedCellValue(GK37:HA37)} -> 7 | HY15: {=FindRedCellValue(GK38:HA38)} -> 7 | JB15: Kesesuaian Jenis Produk | JD15: =1/JJ9 -> 3 | JF15: =1/JJ11 -> 3 | JH15: =1/JJ13 -> 3 | JJ15: 1 | JL15: {=FindRedCellValue(IF34:IV34)} -> 0.33333333 | JN15: {=FindRedCellValue(IF35:IV35)} -> 3 | JP15: {=FindRedCellValue(IF36:IV36)} -> 3 | JR15: {=FindRedCellValue(IF37:IV37)} -> 3 | JT15: {=FindRedCellValue(IF38:IV38)} -> 3 | KW15: Kesesuaian Jenis Produk | KY15: =1/LE9 -> 0.33333333 | LA15: =1/LE11 -> 0.2 | LC15: =1/LE13 -> 0.33333333 | LE15: 1 | LG15: {=FindRedCellValue(KA34:KQ34)} -> 0.33333333 | LI15: {=FindRedCellValue(KA35:KQ35)} -> 3 | LK15: {=FindRedCellValue(KA36:KQ36)} -> 3 | LM15: {=FindRedCellValue(KA37:KQ37)} -> 2 | LO15: {=FindRedCellValue(KA38:KQ38)} -> 4 | MR15: Kesesuaian Jenis Produk | MT15: =1/MZ9 -> 0.2 | MV15: =1/MZ11 -> 0.2 | MX15: =1/MZ13 -> 3 | MZ15: 1 | NB15: {=FindRedCellValue(LV34:ML34)} -> 0.33333333 | ND15: {=FindRedCellValue(LV35:ML35)} -> 0.33333333 | NF15: {=FindRedCellValue(LV36:ML36)} -> 3 | NH15: {=FindRedCellValue(LV37:ML37)} -> 3 | NJ15: {=FindRedCellValue(LV38:ML38)} -> 3 | OM15: Kesesuaian Jenis Produk | OO15: =1/OU9 -> 0.33333333 | OQ15: =1/OU11 -> 0.2 | OS15: =1/OU13 -> 0.2 | OU15: 1 | OW15: {=FindRedCellValue(NQ34:OG34)} -> 0.2 | OY15: {=FindRedCellValue(NQ35:OG35)} -> 3 | PA15: {=FindRedCellValue(NQ36:OG36)} -> 5 | PC15: {=FindRedCellValue(NQ37:OG37)} -> 0.33333333 | PE15: {=FindRedCellValue(NQ38:OG38)} -> 7 | QH15: Kesesuaian Jenis Produk | QJ15: =1/QP9 -> 3 | QL15: =1/QP11 -> 3 | QN15: =1/QP13 -> 3 | QP15: 1 | QR15: {=FindRedCellValue(PL34:QB34)} -> 0.33333333 | QT15: {=FindRedCellValue(PL35:QB35)} -> 3 | QV15: {=FindRedCellValue(PL36:QB36)} -> 3 | QX15: {=FindRedCellValue(PL37:QB37)} -> 3 | QZ15: {=FindRedCellValue(PL38:QB38)} -> 3 | SC15: Kesesuaian Jenis Produk | SE15: =1/SK9 -> 0.33333333 | SG15: =1/SK11 -> 0.2 | SI15: =1/SK13 -> 0.2 | SK15: 1 | SM15: {=FindRedCellValue(RG34:RW34)} -> 0.2 | SO15: {=FindRedCellValue(RG35:RW35)} -> 3 | SQ15: {=FindRedCellValue(RG36:RW36)} -> 5 | SS15: {=FindRedCellValue(RG37:RW37)} -> 0.33333333 | SU15: {=FindRedCellValue(RG38:RW38)} -> 7 | TX15: Kesesuaian Jenis Produk | TZ15: =1/UF9 -> 0.2 | UB15: =1/UF11 -> 0.33333333 | UD15: =1/UF13 -> 0.33333333 | UF15: 1 | UH15: {=FindRedCellValue(TB34:TR34)} -> 0.2 | UJ15: {=FindRedCellValue(TB35:TR35)} -> 7 | UL15: {=FindRedCellValue(TB36:TR36)} -> 0.33333333 | UN15: {=FindRedCellValue(TB37:TR37)} -> 5 | UP15: {=FindRedCellValue(TB38:TR38)} -> 5 | UX15: Kesesuaian Jenis Produk | UZ15: =AVERAGE(AC15,BX15,DS15,FN15,HI15,JD15,KY15,MT15,OO15,QJ15,SE15,TZ15) -> 0.73333333 | VB15: =AVERAGE(AE15,BZ15,DU15,FP15,HK15,JF15,LA15,MV15,OQ15,QL15,SG15,UB15) -> 0.68888889 | VD15: =AVERAGE(AG15,CB15,DW15,FR15,HM15,JH15,LC15,MX15,OS15,QN15,SI15,UD15) -> 1.1888889 | VF15: =AVERAGE(AI15,CD15,DY15,FT15,HO15,JJ15,LE15,MZ15,OU15,QP15,SK15,UF15) -> 1 | VH15: =AVERAGE(AK15,CF15,EA15,FV15,HQ15,JL15,LG15,NB15,OW15,QR15,SM15,UH15) -> 0.26666667 | VJ15: =AVERAGE(AM15,CH15,EC15,FX15,HS15,JN15,LI15,ND15,OY15,QT15,SO15,UJ15) -> 3.2222222 | VL15: =AVERAGE(AO15,CJ15,EE15,FZ15,HU15,JP15,LK15,NF15,PA15,QV15,SQ15,UL15) -> 3.2222222 | VN15: =AVERAGE(AQ15,CL15,EG15,GB15,HW15,JR15,LM15,NH15,PC15,QX15,SS15,UN15) -> 2.8333333 | VP15: =AVERAGE(AS15,CN15,EI15,GD15,HY15,JT15,LO15,NJ15,PE15,QZ15,SU15,UP15) -> 4.8333333
B16: Atribut A | E16: 9 | F16: 8 | G16: 7 | H16: 6 | I16: 5 | J16: 4 | K16: 3 | L16: 2 | M16: 1 | N16: 2 | O16: 3 | P16: 4 | Q16: 5 | R16: 6 | S16: 7 | T16: 8 | U16: 9 | V16: Atribut B | AW16: Atribut A | AZ16: 9 | BA16: 8 | BB16: 7 | BC16: 6 | BD16: 5 | BE16: 4 | BF16: 3 | BG16: 2 | BH16: 1 | BI16: 2 | BJ16: 3 | BK16: 4 | BL16: 5 | BM16: 6 | BN16: 7 | BO16: 8 | BP16: 9 | BQ16: Atribut B | CR16: Atribut A | CU16: 9 | CV16: 8 | CW16: 7 | CX16: 6 | CY16: 5 | CZ16: 4 | DA16: 3 | DB16: 2 | DC16: 1 | DD16: 2 | DE16: 3 | DF16: 4 | DG16: 5 | DH16: 6 | DI16: 7 | DJ16: 8 | DK16: 9 | DL16: Atribut B | EM16: Atribut A | EP16: 9 | EQ16: 8 | ER16: 7 | ES16: 6 | ET16: 5 | EU16: 4 | EV16: 3 | EW16: 2 | EX16: 1 | EY16: 2 | EZ16: 3 | FA16: 4 | FB16: 5 | FC16: 6 | FD16: 7 | FE16: 8 | FF16: 9 | FG16: Atribut B | GH16: Atribut A | GK16: 9 | GL16: 8 | GM16: 7 | GN16: 6 | GO16: 5 | GP16: 4 | GQ16: 3 | GR16: 2 | GS16: 1 | GT16: 2 | GU16: 3 | GV16: 4 | GW16: 5 | GX16: 6 | GY16: 7 | GZ16: 8 | HA16: 9 | HB16: Atribut B | IC16: Atribut A | IF16: 9 | IG16: 8 | IH16: 7 | II16: 6 | IJ16: 5 | IK16: 4 | IL16: 3 | IM16: 2 | IN16: 1 | IO16: 2 | IP16: 3 | IQ16: 4 | IR16: 5 | IS16: 6 | IT16: 7 | IU16: 8 | IV16: 9 | IW16: Atribut B | JX16: Atribut A | KA16: 9 | KB16: 8 | KC16: 7 | KD16: 6 | KE16: 5 | KF16: 4 | KG16: 3 | KH16: 2 | KI16: 1 | KJ16: 2 | KK16: 3 | KL16: 4 | KM16: 5 | KN16: 6 | KO16: 7 | KP16: 8 | KQ16: 9 | KR16: Atribut B | LS16: Atribut A | LV16: 9 | LW16: 8 | LX16: 7 | LY16: 6 | LZ16: 5 | MA16: 4 | MB16: 3 | MC16: 2 | MD16: 1 | ME16: 2 | MF16: 3 | MG16: 4 | MH16: 5 | MI16: 6 | MJ16: 7 | MK16: 8 | ML16: 9 | MM16: Atribut B | NN16: Atribut A | NQ16: 9 | NR16: 8 | NS16: 7 | NT16: 6 | NU16: 5 | NV16: 4 | NW16: 3 | NX16: 2 | NY16: 1 | NZ16: 2 | OA16: 3 | OB16: 4 | OC16: 5 | OD16: 6 | OE16: 7 | OF16: 8 | OG16: 9 | OH16: Atribut B | PI16: Atribut A | PL16: 9 | PM16: 8 | PN16: 7 | PO16: 6 | PP16: 5 | PQ16: 4 | PR16: 3 | PS16: 2 | PT16: 1 | PU16: 2 | PV16: 3 | PW16: 4 | PX16: 5 | PY16: 6 | PZ16: 7 | QA16: 8 | QB16: 9 | QC16: Atribut B | RD16: Atribut A | RG16: 9 | RH16: 8 | RI16: 7 | RJ16: 6 | RK16: 5 | RL16: 4 | RM16: 3 | RN16: 2 | RO16: 1 | RP16: 2 | RQ16: 3 | RR16: 4 | RS16: 5 | RT16: 6 | RU16: 7 | RV16: 8 | RW16: 9 | RX16: Atribut B | SY16: Atribut A | TB16: 9 | TC16: 8 | TD16: 7 | TE16: 6 | TF16: 5 | TG16: 4 | TH16: 3 | TI16: 2 | TJ16: 1 | TK16: 2 | TL16: 3 | TM16: 4 | TN16: 5 | TO16: 6 | TP16: 7 | TQ16: 8 | TR16: 9 | TS16: Atribut B
B17: Akurasi Pemenuhan | V17: Kesesuaian Jumlah Produk | AA17: Kesesuaian Lokasi pengiriman | AC17: =1/AK9 -> 5 | AE17: =1/AK11 -> 5 | AG17: =1/AK13 -> 3 | AI17: =1/AK15 -> 5 | AK17: 1 | AM17: {=FindRedCellValue(E41:U41)} -> 3 | AO17: {=FindRedCellValue(E42:U42)} -> 0.33333333 | AQ17: {=FindRedCellValue(E43:U43)} -> 3 | AS17: {=FindRedCellValue(E44:U44)} -> 3 | AW17: Akurasi Pemenuhan | BQ17: Kesesuaian Jumlah Produk | BV17: Kesesuaian Lokasi pengiriman | BX17: =1/CF9 -> 3 | BZ17: =1/CF11 -> 3 | CB17: =1/CF13 -> 3 | CD17: =1/CF15 -> 5 | CF17: 1 | CH17: {=FindRedCellValue(AZ41:BP41)} -> 3 | CJ17: {=FindRedCellValue(AZ42:BP42)} -> 3 | CL17: {=FindRedCellValue(AZ43:BP43)} -> 5 | CN17: {=FindRedCellValue(AZ44:BP44)} -> 5 | CR17: Akurasi Pemenuhan | DL17: Kesesuaian Jumlah Produk | DQ17: Kesesuaian Lokasi pengiriman | DS17: =1/EA9 -> 5 | DU17: =1/EA11 -> 3 | DW17: =1/EA13 -> 7 | DY17: =1/EA15 -> 3 | EA17: 1 | EC17: {=FindRedCellValue(CU41:DK41)} -> 5 | EE17: {=FindRedCellValue(CU42:DK42)} -> 3 | EG17: {=FindRedCellValue(CU43:DK43)} -> 5 | EI17: {=FindRedCellValue(CU44:DK44)} -> 5 | EM17: Akurasi Pemenuhan | FG17: Kesesuaian Jumlah Produk | FL17: Kesesuaian Lokasi pengiriman | FN17: =1/FV9 -> 3 | FP17: =1/FV11 -> 3 | FR17: =1/FV13 -> 3 | FT17: =1/FV15 -> 3 | FV17: 1 | FX17: {=FindRedCellValue(EP41:FF41)} -> 3 | FZ17: {=FindRedCellValue(EP42:FF42)} -> 3 | GB17: {=FindRedCellValue(EP43:FF43)} -> 5 | GD17: {=FindRedCellValue(EP44:FF44)} -> 7 | GH17: Akurasi Pemenuhan | HB17: Kesesuaian Jumlah Produk | HG17: Kesesuaian Lokasi pengiriman | HI17: =1/HQ9 -> 3 | HK17: =1/HQ11 -> 7 | HM17: =1/HQ13 -> 3 | HO17: =1/HQ15 -> 5 | HQ17: 1 | HS17: {=FindRedCellValue(GK41:HA41)} -> 3 | HU17: {=FindRedCellValue(GK42:HA42)} -> 0.2 | HW17: {=FindRedCellValue(GK43:HA43)} -> 3 | HY17: {=FindRedCellValue(GK44:HA44)} -> 3 | IC17: Akurasi Pemenuhan | IW17: Kesesuaian Jumlah Produk | JB17: Kesesuaian Lokasi pengiriman | JD17: =1/JL9 -> 3 | JF17: =1/JL11 -> 3 | JH17: =1/JL13 -> 3 | JJ17: =1/JL15 -> 3 | JL17: 1 | JN17: {=FindRedCellValue(IF41:IV41)} -> 0.33333333 | JP17: {=FindRedCellValue(IF42:IV42)} -> 0.2 | JR17: {=FindRedCellValue(IF43:IV43)} -> 3 | JT17: {=FindRedCellValue(IF44:IV44)} -> 3 | JX17: Akurasi Pemenuhan | KR17: Kesesuaian Jumlah Produk | KW17: Kesesuaian Lokasi pengiriman | KY17: =1/LG9 -> 5 | LA17: =1/LG11 -> 3 | LC17: =1/LG13 -> 7 | LE17: =1/LG15 -> 3 | LG17: 1 | LI17: {=FindRedCellValue(KA41:KQ41)} -> 5 | LK17: {=FindRedCellValue(KA42:KQ42)} -> 3 | LM17: {=FindRedCellValue(KA43:KQ43)} -> 5 | LO17: {=FindRedCellValue(KA44:KQ44)} -> 5 | LS17: Akurasi Pemenuhan | MM17: Kesesuaian Jumlah Produk | MR17: Kesesuaian Lokasi pengiriman | MT17: =1/NB9 -> 3 | MV17: =1/NB11 -> 3 | MX17: =1/NB13 -> 3 | MZ17: =1/NB15 -> 3 | NB17: 1 | ND17: {=FindRedCellValue(LV41:ML41)} -> 3 | NF17: {=FindRedCellValue(LV42:ML42)} -> 3 | NH17: {=FindRedCellValue(LV43:ML43)} -> 5 | NJ17: {=FindRedCellValue(LV44:ML44)} -> 7 | NN17: Akurasi Pemenuhan | OH17: Kesesuaian Jumlah Produk | OM17: Kesesuaian Lokasi pengiriman | OO17: =1/OW9 -> 5 | OQ17: =1/OW11 -> 5 | OS17: =1/OW13 -> 3 | OU17: =1/OW15 -> 5 | OW17: 1 | OY17: {=FindRedCellValue(NQ41:OG41)} -> 3 | PA17: {=FindRedCellValue(NQ42:OG42)} -> 0.33333333 | PC17: {=FindRedCellValue(NQ43:OG43)} -> 3 | PE17: {=FindRedCellValue(NQ44:OG44)} -> 3 | PI17: Akurasi Pemenuhan | QC17: Kesesuaian Jumlah Produk | QH17: Kesesuaian Lokasi pengiriman | QJ17: =1/QR9 -> 3 | QL17: =1/QR11 -> 3 | QN17: =1/QR13 -> 3 | QP17: =1/QR15 -> 3 | QR17: 1 | QT17: {=FindRedCellValue(PL41:QB41)} -> 0.33333333 | QV17: {=FindRedCellValue(PL42:QB42)} -> 0.2 | QX17: {=FindRedCellValue(PL43:QB43)} -> 3 | QZ17: {=FindRedCellValue(PL44:QB44)} -> 3 | RD17: Akurasi Pemenuhan | RX17: Kesesuaian Jumlah Produk | SC17: Kesesuaian Lokasi pengiriman | SE17: =1/SM9 -> 5 | SG17: =1/SM11 -> 5 | SI17: =1/SM13 -> 3 | SK17: =1/SM15 -> 5 | SM17: 1 | SO17: {=FindRedCellValue(RG41:RW41)} -> 3 | SQ17: {=FindRedCellValue(RG42:RW42)} -> 0.33333333 | SS17: {=FindRedCellValue(RG43:RW43)} -> 3 | SU17: {=FindRedCellValue(RG44:RW44)} -> 3 | SY17: Akurasi Pemenuhan | TS17: Kesesuaian Jumlah Produk | TX17: Kesesuaian Lokasi pengiriman | TZ17: =1/UH9 -> 3 | UB17: =1/UH11 -> 3 | UD17: =1/UH13 -> 3 | UF17: =1/UH15 -> 5 | UH17: 1 | UJ17: {=FindRedCellValue(TB41:TR41)} -> 3 | UL17: {=FindRedCellValue(TB42:TR42)} -> 3 | UN17: {=FindRedCellValue(TB43:TR43)} -> 5 | UP17: {=FindRedCellValue(TB44:TR44)} -> 5 | UX17: Kesesuaian Lokasi pengiriman | UZ17: =AVERAGE(AC17,BX17,DS17,FN17,HI17,JD17,KY17,MT17,OO17,QJ17,SE17,TZ17) -> 3.8333333 | VB17: =AVERAGE(AE17,BZ17,DU17,FP17,HK17,JF17,LA17,MV17,OQ17,QL17,SG17,UB17) -> 3.8333333 | VD17: =AVERAGE(AG17,CB17,DW17,FR17,HM17,JH17,LC17,MX17,OS17,QN17,SI17,UD17) -> 3.6666667 | VF17: =AVERAGE(AI17,CD17,DY17,FT17,HO17,JJ17,LE17,MZ17,OU17,QP17,SK17,UF17) -> 4 | VH17: =AVERAGE(AK17,CF17,EA17,FV17,HQ17,JL17,LG17,NB17,OW17,QR17,SM17,UH17) -> 1 | VJ17: =AVERAGE(AM17,CH17,EC17,FX17,HS17,JN17,LI17,ND17,OY17,QT17,SO17,UJ17) -> 2.8888889 | VL17: =AVERAGE(AO17,CJ17,EE17,FZ17,HU17,JP17,LK17,NF17,PA17,QV17,SQ17,UL17) -> 1.6333333 | VN17: =AVERAGE(AQ17,CL17,EG17,GB17,HW17,JR17,LM17,NH17,PC17,QX17,SS17,UN17) -> 4 | VP17: =AVERAGE(AS17,CN17,EI17,GD17,HY17,JT17,LO17,NJ17,PE17,QZ17,SU17,UP17) -> 4.3333333
B18: Akurasi Pemenuhan | V18: Kesesuaian Jenis Produk | AW18: Akurasi Pemenuhan | BQ18: Kesesuaian Jenis Produk | CR18: Akurasi Pemenuhan | DL18: Kesesuaian Jenis Produk | EM18: Akurasi Pemenuhan | FG18: Kesesuaian Jenis Produk | GH18: Akurasi Pemenuhan | HB18: Kesesuaian Jenis Produk | IC18: Akurasi Pemenuhan | IW18: Kesesuaian Jenis Produk | JX18: Akurasi Pemenuhan | KR18: Kesesuaian Jenis Produk | LS18: Akurasi Pemenuhan | MM18: Kesesuaian Jenis Produk | NN18: Akurasi Pemenuhan | OH18: Kesesuaian Jenis Produk | PI18: Akurasi Pemenuhan | QC18: Kesesuaian Jenis Produk | RD18: Akurasi Pemenuhan | RX18: Kesesuaian Jenis Produk | SY18: Akurasi Pemenuhan | TS18: Kesesuaian Jenis Produk
B19: Akurasi Pemenuhan | V19: Kesesuaian Lokasi Pengiriman | AA19: Kesesuaian Waktu Pengiriman | AC19: =1/AM9 -> 3 | AE19: =1/AM11 -> 7 | AG19: =1/AM13 -> 0.14285714 | AI19: =1/AM15 -> 0.33333333 | AK19: =1/AM17 -> 0.33333333 | AM19: 1 | AO19: {=FindRedCellValue(E47:U47)} -> 0.33333333 | AQ19: {=FindRedCellValue(E48:U48)} -> 0.33333333 | AS19: {=FindRedCellValue(E49:U49)} -> 7 | AW19: Akurasi Pemenuhan | BQ19: Kesesuaian Lokasi Pengiriman | BV19: Kesesuaian Waktu Pengiriman | BX19: =1/CH9 -> 5 | BZ19: =1/CH11 -> 3 | CB19: =1/CH13 -> 0.33333333 | CD19: =1/CH15 -> 0.14285714 | CF19: =1/CH17 -> 0.33333333 | CH19: 1 | CJ19: {=FindRedCellValue(AZ47:BP47)} -> 0.11111111 | CL19: {=FindRedCellValue(AZ48:BP48)} -> 7 | CN19: {=FindRedCellValue(AZ49:BP49)} -> 5 | CR19: Akurasi Pemenuhan | DL19: Kesesuaian Lokasi Pengiriman | DQ19: Kesesuaian Waktu Pengiriman | DS19: =1/EC9 -> 0.33333333 | DU19: =1/EC11 -> 3 | DW19: =1/EC13 -> 0.2 | DY19: =1/EC15 -> 0.33333333 | EA19: =1/EC17 -> 0.2 | EC19: 1 | EE19: {=FindRedCellValue(CU47:DK47)} -> 9 | EG19: {=FindRedCellValue(CU48:DK48)} -> 0.11111111 | EI19: {=FindRedCellValue(CU49:DK49)} -> 0.33333333 | EM19: Akurasi Pemenuhan | FG19: Kesesuaian Lokasi Pengiriman | FL19: Kesesuaian Waktu Pengiriman | FN19: =1/FX9 -> 0.33333333 | FP19: =1/FX11 -> 0.33333333 | FR19: =1/FX13 -> 0.2 | FT19: =1/FX15 -> 3 | FV19: =1/FX17 -> 0.33333333 | FX19: 1 | FZ19: {=FindRedCellValue(EP47:FF47)} -> 0.33333333 | GB19: {=FindRedCellValue(EP48:FF48)} -> 3 | GD19: {=FindRedCellValue(EP49:FF49)} -> 3 | GH19: Akurasi Pemenuhan | HB19: Kesesuaian Lokasi Pengiriman | HG19: Kesesuaian Waktu Pengiriman | HI19: =1/HS9 -> 0.2 | HK19: =1/HS11 -> 9 | HM19: =1/HS13 -> 0.33333333 | HO19: =1/HS15 -> 0.33333333 | HQ19: =1/HS17 -> 0.33333333 | HS19: 1 | HU19: {=FindRedCellValue(GK47:HA47)} -> 0.33333333 | HW19: {=FindRedCellValue(GK48:HA48)} -> 3 | HY19: {=FindRedCellValue(GK49:HA49)} -> 0.2 | IC19: Akurasi Pemenuhan | IW19: Kesesuaian Lokasi Pengiriman | JB19: Kesesuaian Waktu Pengiriman | JD19: =1/JN9 -> 0.33333333 | JF19: =1/JN11 -> 0.33333333 | JH19: =1/JN13 -> 0.33333333 | JJ19: =1/JN15 -> 0.33333333 | JL19: =1/JN17 -> 3 | JN19: 1 | JP19: {=FindRedCellValue(IF47:IV47)} -> 0.33333333 | JR19: {=FindRedCellValue(IF48:IV48)} -> 0.2 | JT19: {=FindRedCellValue(IF49:IV49)} -> 0.2 | JX19: Akurasi Pemenuhan | KR19: Kesesuaian Lokasi Pengiriman | KW19: Kesesuaian Waktu Pengiriman | KY19: =1/LI9 -> 0.33333333 | LA19: =1/LI11 -> 3 | LC19: =1/LI13 -> 0.2 | LE19: =1/LI15 -> 0.33333333 | LG19: =1/LI17 -> 0.2 | LI19: 1 | LK19: {=FindRedCellValue(KA47:KQ47)} -> 9 | LM19: {=FindRedCellValue(KA48:KQ48)} -> 0.11111111 | LO19: {=FindRedCellValue(KA49:KQ49)} -> 0.33333333 | LS19: Akurasi Pemenuhan | MM19: Kesesuaian Lokasi Pengiriman | MR19: Kesesuaian Waktu Pengiriman | MT19: =1/ND9 -> 0.33333333 | MV19: =1/ND11 -> 0.33333333 | MX19: =1/ND13 -> 0.2 | MZ19: =1/ND15 -> 3 | NB19: =1/ND17 -> 0.33333333 | ND19: 1 | NF19: {=FindRedCellValue(LV47:ML47)} -> 0.33333333 | NH19: {=FindRedCellValue(LV48:ML48)} -> 3 | NJ19: {=FindRedCellValue(LV49:ML49)} -> 3 | NN19: Akurasi Pemenuhan | OH19: Kesesuaian Lokasi Pengiriman | OM19: Kesesuaian Waktu Pengiriman | OO19: =1/OY9 -> 3 | OQ19: =1/OY11 -> 7 | OS19: =1/OY13 -> 0.14285714 | OU19: =1/OY15 -> 0.33333333 | OW19: =1/OY17 -> 0.33333333 | OY19: 1 | PA19: {=FindRedCellValue(NQ47:OG47)} -> 0.33333333 | PC19: {=FindRedCellValue(NQ48:OG48)} -> 0.33333333 | PE19: {=FindRedCellValue(NQ49:OG49)} -> 7 | PI19: Akurasi Pemenuhan | QC19: Kesesuaian Lokasi Pengiriman | QH19: Kesesuaian Waktu Pengiriman | QJ19: =1/QT9 -> 0.33333333 | QL19: =1/QT11 -> 0.33333333 | QN19: =1/QT13 -> 0.33333333 | QP19: =1/QT15 -> 0.33333333 | QR19: =1/QT17 -> 3 | QT19: 1 | QV19: {=FindRedCellValue(PL47:QB47)} -> 0.33333333 | QX19: {=FindRedCellValue(PL48:QB48)} -> 0.2 | QZ19: {=FindRedCellValue(PL49:QB49)} -> 0.2 | RD19: Akurasi Pemenuhan | RX19: Kesesuaian Lokasi Pengiriman | SC19: Kesesuaian Waktu Pengiriman | SE19: =1/SO9 -> 3 | SG19: =1/SO11 -> 7 | SI19: =1/SO13 -> 0.14285714 | SK19: =1/SO15 -> 0.33333333 | SM19: =1/SO17 -> 0.33333333 | SO19: 1 | SQ19: {=FindRedCellValue(RG47:RW47)} -> 0.33333333 | SS19: {=FindRedCellValue(RG48:RW48)} -> 0.33333333 | SU19: {=FindRedCellValue(RG49:RW49)} -> 7 | SY19: Akurasi Pemenuhan | TS19: Kesesuaian Lokasi Pengiriman | TX19: Kesesuaian Waktu Pengiriman | TZ19: =1/UJ9 -> 5 | UB19: =1/UJ11 -> 3 | UD19: =1/UJ13 -> 0.33333333 | UF19: =1/UJ15 -> 0.14285714 | UH19: =1/UJ17 -> 0.33333333 | UJ19: 1 | UL19: {=FindRedCellValue(TB47:TR47)} -> 0.11111111 | UN19: {=FindRedCellValue(TB48:TR48)} -> 7 | UP19: {=FindRedCellValue(TB49:TR49)} -> 5 | UX19: Kesesuaian Waktu Pengiriman | UZ19: =AVERAGE(AC19,BX19,DS19,FN19,HI19,JD19,KY19,MT19,OO19,QJ19,SE19,TZ19) -> 1.7666667 | VB19: =AVERAGE(AE19,BZ19,DU19,FP19,HK19,JF19,LA19,MV19,OQ19,QL19,SG19,UB19) -> 3.6111111 | VD19: =AVERAGE(AG19,CB19,DW19,FR19,HM19,JH19,LC19,MX19,OS19,QN19,SI19,UD19) -> 0.24126984 | VF19: =AVERAGE(AI19,CD19,DY19,FT19,HO19,JJ19,LE19,MZ19,OU19,QP19,SK19,UF19) -> 0.74603175 | VH19: =AVERAGE(AK19,CF19,EA19,FV19,HQ19,JL19,LG19,NB19,OW19,QR19,SM19,UH19) -> 0.75555556 | VJ19: =AVERAGE(AM19,CH19,EC19,FX19,HS19,JN19,LI19,ND19,OY19,QT19,SO19,UJ19) -> 1 | VL19: =AVERAGE(AO19,CJ19,EE19,FZ19,HU19,JP19,LK19,NF19,PA19,QV19,SQ19,UL19) -> 1.7407407 | VN19: =AVERAGE(AQ19,CL19,EG19,GB19,HW19,JR19,LM19,NH19,PC19,QX19,SS19,UN19) -> 2.0518519 | VP19: =AVERAGE(AS19,CN19,EI19,GD19,HY19,JT19,LO19,NJ19,PE19,QZ19,SU19,UP19) -> 3.1888889
B20: Akurasi Pemenuhan | V20: Kesesuaian Waktu Pengiriman | AW20: Akurasi Pemenuhan | BQ20: Kesesuaian Waktu Pengiriman | CR20: Akurasi Pemenuhan | DL20: Kesesuaian Waktu Pengiriman | EM20: Akurasi Pemenuhan | FG20: Kesesuaian Waktu Pengiriman | GH20: Akurasi Pemenuhan | HB20: Kesesuaian Waktu Pengiriman | IC20: Akurasi Pemenuhan | IW20: Kesesuaian Waktu Pengiriman | JX20: Akurasi Pemenuhan | KR20: Kesesuaian Waktu Pengiriman | LS20: Akurasi Pemenuhan | MM20: Kesesuaian Waktu Pengiriman | NN20: Akurasi Pemenuhan | OH20: Kesesuaian Waktu Pengiriman | PI20: Akurasi Pemenuhan | QC20: Kesesuaian Waktu Pengiriman | RD20: Akurasi Pemenuhan | RX20: Kesesuaian Waktu Pengiriman | SY20: Akurasi Pemenuhan | TS20: Kesesuaian Waktu Pengiriman
B21: Akurasi Pemenuhan | V21: Akurasi Kondisi Pesanan | AA21: Akurasi Kondisi Pesanan | AC21: =1/AO9 -> 0.2 | AE21: =1/AO11 -> 0.33333333 | AG21: =1/AO13 -> 0.11111111 | AI21: =1/AO15 -> 0.2 | AK21: =1/AO17 -> 3 | AM21: =1/AO19 -> 3 | AO21: 1 | AQ21: {=FindRedCellValue(E52:U52)} -> 0.33333333 | AS21: {=FindRedCellValue(E53:U53)} -> 3 | AW21: Akurasi Pemenuhan | BQ21: Akurasi Kondisi Pesanan | BV21: Akurasi Kondisi Pesanan | BX21: =1/CJ9 -> 0.33333333 | BZ21: =1/CJ11 -> 3 | CB21: =1/CJ13 -> 0.2 | CD21: =1/CJ15 -> 3 | CF21: =1/CJ17 -> 0.33333333 | CH21: =1/CJ19 -> 9 | CJ21: 1 | CL21: {=FindRedCellValue(AZ52:BP52)} -> 0.5 | CN21: {=FindRedCellValue(AZ53:BP53)} -> 5 | CR21: Akurasi Pemenuhan | DL21: Akurasi Kondisi Pesanan | DQ21: Akurasi Kondisi Pesanan | DS21: =1/EE9 -> 5 | DU21: =1/EE11 -> 0.33333333 | DW21: =1/EE13 -> 0.2 | DY21: =1/EE15 -> 0.33333333 | EA21: =1/EE17 -> 0.33333333 | EC21: =1/EE19 -> 0.11111111 | EE21: 1 | EG21: {=FindRedCellValue(CU52:DK52)} -> 0.33333333 | EI21: {=FindRedCellValue(CU53:DK53)} -> 0.33333333 | EM21: Akurasi Pemenuhan | FG21: Akurasi Kondisi Pesanan | FL21: Akurasi Kondisi Pesanan | FN21: =1/FZ9 -> 7 | FP21: =1/FZ11 -> 5 | FR21: =1/FZ13 -> 0.33333333 | FT21: =1/FZ15 -> 0.33333333 | FV21: =1/FZ17 -> 0.33333333 | FX21: =1/FZ19 -> 3 | FZ21: 1 | GB21: {=FindRedCellValue(EP52:FF52)} -> 7 | GD21: {=FindRedCellValue(EP53:FF53)} -> 7 | GH21: Akurasi Pemenuhan | HB21: Akurasi Kondisi Pesanan | HG21: Akurasi Kondisi Pesanan | HI21: =1/HU9 -> 2 | HK21: =1/HU11 -> 0.33333333 | HM21: =1/HU13 -> 0.33333333 | HO21: =1/HU15 -> 0.2 | HQ21: =1/HU17 -> 5 | HS21: =1/HU19 -> 3 | HU21: 1 | HW21: {=FindRedCellValue(GK52:HA52)} -> 3 | HY21: {=FindRedCellValue(GK53:HA53)} -> 0.2 | IC21: Akurasi Pemenuhan | IW21: Akurasi Kondisi Pesanan | JB21: Akurasi Kondisi Pesanan | JD21: =1/JP9 -> 0.33333333 | JF21: =1/JP11 -> 0.33333333 | JH21: =1/JP13 -> 0.33333333 | JJ21: =1/JP15 -> 0.33333333 | JL21: =1/JP17 -> 5 | JN21: =1/JP19 -> 3 | JP21: 1 | JR21: {=FindRedCellValue(IF52:IV52)} -> 3 | JT21: {=FindRedCellValue(IF53:IV53)} -> 0.33333333 | JX21: Akurasi Pemenuhan | KR21: Akurasi Kondisi Pesanan | KW21: Akurasi Kondisi Pesanan | KY21: =1/LK9 -> 5 | LA21: =1/LK11 -> 0.33333333 | LC21: =1/LK13 -> 0.2 | LE21: =1/LK15 -> 0.33333333 | LG21: =1/LK17 -> 0.33333333 | LI21: =1/LK19 -> 0.11111111 | LK21: 1 | LM21: {=FindRedCellValue(KA52:KQ52)} -> 0.33333333 | LO21: {=FindRedCellValue(KA53:KQ53)} -> 0.33333333 | LS21: Akurasi Pemenuhan | MM21: Akurasi Kondisi Pesanan | MR21: Akurasi Kondisi Pesanan | MT21: =1/NF9 -> 7 | MV21: =1/NF11 -> 5 | MX21: =1/NF13 -> 0.33333333 | MZ21: =1/NF15 -> 0.33333333 | NB21: =1/NF17 -> 0.33333333 | ND21: =1/NF19 -> 3 | NF21: 1 | NH21: {=FindRedCellValue(LV52:ML52)} -> 7 | NJ21: {=FindRedCellValue(LV53:ML53)} -> 7 | NN21: Akurasi Pemenuhan | OH21: Akurasi Kondisi Pesanan | OM21: Akurasi Kondisi Pesanan | OO21: =1/PA9 -> 0.2 | OQ21: =1/PA11 -> 0.33333333 | OS21: =1/PA13 -> 0.11111111 | OU21: =1/PA15 -> 0.2 | OW21: =1/PA17 -> 3 | OY21: =1/PA19 -> 3 | PA21: 1 | PC21: {=FindRedCellValue(NQ52:OG52)} -> 0.33333333 | PE21: {=FindRedCellValue(NQ53:OG53)} -> 3 | PI21: Akurasi Pemenuhan | QC21: Akurasi Kondisi Pesanan | QH21: Akurasi Kondisi Pesanan | QJ21: =1/QV9 -> 0.33333333 | QL21: =1/QV11 -> 0.33333333 | QN21: =1/QV13 -> 0.33333333 | QP21: =1/QV15 -> 0.33333333 | QR21: =1/QV17 -> 5 | QT21: =1/QV19 -> 3 | QV21: 1 | QX21: {=FindRedCellValue(PL52:QB52)} -> 3 | QZ21: {=FindRedCellValue(PL53:QB53)} -> 0.33333333 | RD21: Akurasi Pemenuhan | RX21: Akurasi Kondisi Pesanan | SC21: Akurasi Kondisi Pesanan | SE21: =1/SQ9 -> 0.2 | SG21: =1/SQ11 -> 0.33333333 | SI21: =1/SQ13 -> 0.11111111 | SK21: =1/SQ15 -> 0.2 | SM21: =1/SQ17 -> 3 | SO21: =1/SQ19 -> 3 | SQ21: 1 | SS21: {=FindRedCellValue(RG52:RW52)} -> 0.33333333 | SU21: {=FindRedCellValue(RG53:RW53)} -> 3 | SY21: Akurasi Pemenuhan | TS21: Akurasi Kondisi Pesanan | TX21: Akurasi Kondisi Pesanan | TZ21: =1/UL9 -> 0.33333333 | UB21: =1/UL11 -> 3 | UD21: =1/UL13 -> 0.2 | UF21: =1/UL15 -> 3 | UH21: =1/UL17 -> 0.33333333 | UJ21: =1/UL19 -> 9 | UL21: 1 | UN21: {=FindRedCellValue(TB52:TR52)} -> 0.5 | UP21: {=FindRedCellValue(TB53:TR53)} -> 5 | UX21: Akurasi Kondisi Pesanan | UZ21: =AVERAGE(AC21,BX21,DS21,FN21,HI21,JD21,KY21,MT21,OO21,QJ21,SE21,TZ21) -> 2.3277778 | VB21: =AVERAGE(AE21,BZ21,DU21,FP21,HK21,JF21,LA21,MV21,OQ21,QL21,SG21,UB21) -> 1.5555556 | VD21: =AVERAGE(AG21,CB21,DW21,FR21,HM21,JH21,LC21,MX21,OS21,QN21,SI21,UD21) -> 0.23333333 | VF21: =AVERAGE(AI21,CD21,DY21,FT21,HO21,JJ21,LE21,MZ21,OU21,QP21,SK21,UF21) -> 0.73333333 | VH21: =AVERAGE(AK21,CF21,EA21,FV21,HQ21,JL21,LG21,NB21,OW21,QR21,SM21,UH21) -> 2.1666667 | VJ21: =AVERAGE(AM21,CH21,EC21,FX21,HS21,JN21,LI21,ND21,OY21,QT21,SO21,UJ21) -> 3.5185185 | VL21: =AVERAGE(AO21,CJ21,EE21,FZ21,HU21,JP21,LK21,NF21,PA21,QV21,SQ21,UL21) -> 1 | VN21: =AVERAGE(AQ21,CL21,EG21,GB21,HW21,JR21,LM21,NH21,PC21,QX21,SS21,UN21) -> 2.1388889 | VP21: =AVERAGE(AS21,CN21,EI21,GD21,HY21,JT21,LO21,NJ21,PE21,QZ21,SU21,UP21) -> 2.8777778
B22: Akurasi Pemenuhan | V22: Kelayakan Produk | AW22: Akurasi Pemenuhan | BQ22: Kelayakan Produk | CR22: Akurasi Pemenuhan | DL22: Kelayakan Produk | EM22: Akurasi Pemenuhan | FG22: Kelayakan Produk | GH22: Akurasi Pemenuhan | HB22: Kelayakan Produk | IC22: Akurasi Pemenuhan | IW22: Kelayakan Produk | JX22: Akurasi Pemenuhan | KR22: Kelayakan Produk | LS22: Akurasi Pemenuhan | MM22: Kelayakan Produk | NN22: Akurasi Pemenuhan | OH22: Kelayakan Produk | PI22: Akurasi Pemenuhan | QC22: Kelayakan Produk | RD22: Akurasi Pemenuhan | RX22: Kelayakan Produk | SY22: Akurasi Pemenuhan | TS22: Kelayakan Produk
